<?xml version="1.0" ?>
<robot name="g1_21j">
  <link name="pelvis_link">
    <visual>
      <origin xyz="0 0 0" rpy="0 0 0"/>
      <geometry>
        <mesh filename="meshes/pelvis.STL"/>
      </geometry>
      <material name="dark">
        <color rgba="0.2 0.2 0.2 1"/>
      </material>
    </visual>
    <inertial>
      <origin xyz="0 0 -0.0760300603" rpy="0 0 0"/>
      <mass value="3.814"/>
      <inertia ixx="0.01055488209" ixy="0" ixz="2.1e-06" iyy="0.009314782086" iyz="0" izz="0.0079185"/>
    </inertial>
    <visual>
      <origin xyz="0 0 0" rpy="0 -0 0"/>
      <geometry>
        <mesh filename="meshes/pelvis_contour_link.STL"/>
      </geometry>
      <material name="white">
        <color rgba="0.7 0.7 0.7 1"/>
      </material>
    </visual>
  </link>
  <link name="left_hip_pitch_link">
    <inertial>
      <origin xyz="0.002741 0.047791 -0.02606" rpy="0 0 0"/>
      <mass value="1.35"/>
      <inertia ixx="0.001811" ixy="3.68E-05" ixz="-3.44E-05" iyy="0.0014193" iyz="0.000171" izz="0.0012812"/>
    </inertial>
    <visual>
      <origin xyz="0 0 0" rpy="0 0 0"/>
      <geometry>
        <mesh filename="meshes/left_hip_pitch_link.STL"/>
      </geometry>
      <material name="dark">
        <color rgba="0.2 0.2 0.2 1"/>
      </material>
    </visual>
  </link>
  <joint name="left_hip_pitch_joint" type="revolute">
    <origin xyz="0 0.064452 -0.1027" rpy="0 0 0"/>
    <parent link="pelvis_link"/>
    <child link="left_hip_pitch_link"/>
    <axis xyz="0 1 0"/>
    <limit lower="-2.5307" upper="2.8798" effort="88" velocity="12"/>
  </joint>
  <link name="left_hip_roll_link">
    <inertial>
      <origin xyz="0.029812 -0.001045 -0.087934" rpy="0 0 0"/>
      <mass value="1.52"/>
      <inertia ixx="0.0023773" ixy="-3.8E-06" ixz="-0.0003908" iyy="0.0024123" iyz="1.84E-05" izz="0.0016595"/>
    </inertial>
    <visual>
      <origin xyz="0 0 0" rpy="0 0 0"/>
      <geometry>
        <mesh filename="meshes/left_hip_roll_link.STL"/>
      </geometry>
      <material name="white">
        <color rgba="0.7 0.7 0.7 1"/>
      </material>
    </visual>
    <collision>
      <origin xyz="0.02 0 -0.1" rpy="0 0.0524 0"/>
      <geometry>
        <cylinder radius="0.045" length="0.25"/>
      </geometry>
    </collision>
  </link>
  <joint name="left_hip_roll_joint" type="revolute">
    <origin xyz="0 0.052 -0.030465" rpy="0 -0.1749 0"/>
    <parent link="left_hip_pitch_link"/>
    <child link="left_hip_roll_link"/>
    <axis xyz="1 0 0"/>
    <limit lower="-0.5236" upper="2.9671" effort="88" velocity="12"/>
  </joint>
  <link name="left_hip_yaw_link">
    <inertial>
      <origin xyz="-0.057709 -0.010981 -0.15078" rpy="0 0 0"/>
      <mass value="1.702"/>
      <inertia ixx="0.0057774" ixy="-0.0005411" ixz="-0.0023948" iyy="0.0076124" iyz="-0.0007072" izz="0.003149"/>
    </inertial>
    <visual>
      <origin xyz="0 0 0" rpy="0 0 0"/>
      <geometry>
        <mesh filename="meshes/left_hip_yaw_link.STL"/>
      </geometry>
      <material name="white">
        <color rgba="0.7 0.7 0.7 1"/>
      </material>
    </visual>
  </link>
  <joint name="left_hip_yaw_joint" type="revolute">
    <origin xyz="0.025001 0 -0.12412" rpy="0 0 0"/>
    <parent link="left_hip_roll_link"/>
    <child link="left_hip_yaw_link"/>
    <axis xyz="0 0 1"/>
    <limit lower="-2.7576" upper="2.7576" effort="88" velocity="12"/>
  </joint>
  <link name="left_knee_link">
    <inertial>
      <origin xyz="0.005457 0.003964 -0.12074" rpy="0 0 0"/>
      <mass value="1.932"/>
      <inertia ixx="0.011329" ixy="4.82E-05" ixz="-4.49E-05" iyy="0.011277" iyz="-0.0007146" izz="0.0015168"/>
    </inertial>
    <visual>
      <origin xyz="0 0 0" rpy="0 0 0"/>
      <geometry>
        <mesh filename="meshes/left_knee_link.STL"/>
      </geometry>
      <material name="white">
        <color rgba="0.7 0.7 0.7 1"/>
      </material>
    </visual>
    <collision>
      <origin xyz="0 0 -0.15" rpy="0 0 0"/>
      <geometry>
        <cylinder radius="0.05" length="0.3"/>
      </geometry>
    </collision>
  </link>
  <joint name="left_knee_joint" type="revolute">
    <origin xyz="-0.078273 0.0021489 -0.17734" rpy="0 0.1749 0"/>
    <parent link="left_hip_yaw_link"/>
    <child link="left_knee_link"/>
    <axis xyz="0 1 0"/>
    <limit lower="-0.087267" upper="2.8798" effort="139" velocity="12"/>
  </joint>
  <link name="left_ankle_pitch_link">
    <inertial>
      <origin xyz="-0.007269 0 0.011137" rpy="0 0 0"/>
      <mass value="0.074"/>
      <inertia ixx="8.4E-06" ixy="0" ixz="-2.9E-06" iyy="1.89E-05" iyz="0" izz="1.26E-05"/>
    </inertial>
    <visual>
      <origin xyz="0 0 0" rpy="0 0 0"/>
      <geometry>
        <mesh filename="meshes/left_ankle_pitch_link.STL"/>
      </geometry>
      <material name="white">
        <color rgba="0.7 0.7 0.7 1"/>
      </material>
    </visual>
  </link>
  <joint name="left_ankle_pitch_joint" type="revolute">
    <origin xyz="0 -9.4445E-05 -0.30001" rpy="0 0 0"/>
    <parent link="left_knee_link"/>
    <child link="left_ankle_pitch_link"/>
    <axis xyz="0 1 0"/>
    <limit lower="-0.87267" upper="0.5236" effort="50" velocity="12"/>
  </joint>
  <link name="left_ankle_roll_link">
    <visual>
      <origin xyz="0 0 0" rpy="0 0 0"/>
      <geometry>
        <mesh filename="meshes/left_ankle_roll_link.STL"/>
      </geometry>
      <material name="dark">
        <color rgba="0.2 0.2 0.2 1"/>
      </material>
    </visual>
    <collision>
      <origin xyz="-0.05 0.025 -0.03" rpy="0 0 0"/>
      <geometry>
        <sphere radius="0.005"/>
      </geometry>
    </collision>
    <collision>
      <origin xyz="-0.05 -0.025 -0.03" rpy="0 0 0"/>
      <geometry>
        <sphere radius="0.005"/>
      </geometry>
    </collision>
    <collision>
      <origin xyz="0.12 0.03 -0.03" rpy="0 0 0"/>
      <geometry>
        <sphere radius="0.005"/>
      </geometry>
    </collision>
    <collision>
      <origin xyz="0.12 -0.03 -0.03" rpy="0 0 0"/>
      <geometry>
        <sphere radius="0.005"/>
      </geometry>
    </collision>
    <inertial>
      <origin xyz="0.026505 0 -0.016425" rpy="0 0 0"/>
      <mass value="0.608"/>
      <inertia ixx="0.0002231" ixy="2e-07" ixz="8.91e-05" iyy="0.0016161" iyz="-1e-07" izz="0.0016667"/>
    </inertial>
  </link>
  <joint name="left_ankle_roll_joint" type="revolute">
    <origin xyz="0 0 -0.017558" rpy="0 0 0"/>
    <parent link="left_ankle_pitch_link"/>
    <child link="left_ankle_roll_link"/>
    <axis xyz="1 0 0"/>
    <limit lower="-0.2618" upper="0.2618" effort="50" velocity="12"/>
  </joint>
  <link name="right_hip_pitch_link">
    <inertial>
      <origin xyz="0.002741 -0.047791 -0.02606" rpy="0 0 0"/>
      <mass value="1.35"/>
      <inertia ixx="0.001811" ixy="-3.68E-05" ixz="-3.44E-05" iyy="0.0014193" iyz="-0.000171" izz="0.0012812"/>
    </inertial>
    <visual>
      <origin xyz="0 0 0" rpy="0 0 0"/>
      <geometry>
        <mesh filename="meshes/right_hip_pitch_link.STL"/>
      </geometry>
      <material name="dark">
        <color rgba="0.2 0.2 0.2 1"/>
      </material>
    </visual>
  </link>
  <joint name="right_hip_pitch_joint" type="revolute">
    <origin xyz="0 -0.064452 -0.1027" rpy="0 0 0"/>
    <parent link="pelvis_link"/>
    <child link="right_hip_pitch_link"/>
    <axis xyz="0 1 0"/>
    <limit lower="-2.5307" upper="2.8798" effort="88" velocity="12"/>
  </joint>
  <link name="right_hip_roll_link">
    <inertial>
      <origin xyz="0.029812 0.001045 -0.087934" rpy="0 0 0"/>
      <mass value="1.52"/>
      <inertia ixx="0.0023773" ixy="3.8E-06" ixz="-0.0003908" iyy="0.0024123" iyz="-1.84E-05" izz="0.0016595"/>
    </inertial>
    <visual>
      <origin xyz="0 0 0" rpy="0 0 0"/>
      <geometry>
        <mesh filename="meshes/right_hip_roll_link.STL"/>
      </geometry>
      <material name="white">
        <color rgba="0.7 0.7 0.7 1"/>
      </material>
    </visual>
    <collision>
      <origin xyz="0.02 0 -0.1" rpy="0 -0.0524 0"/>
      <geometry>
        <cylinder radius="0.045" length="0.25"/>
      </geometry>
    </collision>
  </link>
  <joint name="right_hip_roll_joint" type="revolute">
    <origin xyz="0 -0.052 -0.030465" rpy="0 -0.1749 0"/>
    <parent link="right_hip_pitch_link"/>
    <child link="right_hip_roll_link"/>
    <axis xyz="1 0 0"/>
    <limit lower="-2.9671" upper="0.5236" effort="88" velocity="12"/>
  </joint>
  <link name="right_hip_yaw_link">
    <inertial>
      <origin xyz="-0.057709 0.010981 -0.15078" rpy="0 0 0"/>
      <mass value="1.702"/>
      <inertia ixx="0.0057774" ixy="0.0005411" ixz="-0.0023948" iyy="0.0076124" iyz="0.0007072" izz="0.003149"/>
    </inertial>
    <visual>
      <origin xyz="0 0 0" rpy="0 0 0"/>
      <geometry>
        <mesh filename="meshes/right_hip_yaw_link.STL"/>
      </geometry>
      <material name="white">
        <color rgba="0.7 0.7 0.7 1"/>
      </material>
    </visual>
  </link>
  <joint name="right_hip_yaw_joint" type="revolute">
    <origin xyz="0.025001 0 -0.12412" rpy="0 0 0"/>
    <parent link="right_hip_roll_link"/>
    <child link="right_hip_yaw_link"/>
    <axis xyz="0 0 1"/>
    <limit lower="-2.7576" upper="2.7576" effort="88" velocity="12"/>
  </joint>
  <link name="right_knee_link">
    <inertial>
      <origin xyz="0.005457 -0.003964 -0.12074" rpy="0 0 0"/>
      <mass value="1.932"/>
      <inertia ixx="0.011329" ixy="-4.82E-05" ixz="4.49E-05" iyy="0.011277" iyz="0.0007146" izz="0.0015168"/>
    </inertial>
    <visual>
      <origin xyz="0 0 0" rpy="0 0 0"/>
      <geometry>
        <mesh filename="meshes/right_knee_link.STL"/>
      </geometry>
      <material name="white">
        <color rgba="0.7 0.7 0.7 1"/>
      </material>
    </visual>
    <collision>
      <origin xyz="0 0 -0.15" rpy="0 0 0"/>
      <geometry>
        <cylinder radius="0.05" length="0.3"/>
      </geometry>
    </collision>
  </link>
  <joint name="right_knee_joint" type="revolute">
    <origin xyz="-0.078273 -0.0021489 -0.17734" rpy="0 0.1749 0"/>
    <parent link="right_hip_yaw_link"/>
    <child link="right_knee_link"/>
    <axis xyz="0 1 0"/>
    <limit lower="-0.087267" upper="2.8798" effort="139" velocity="12"/>
  </joint>
  <link name="right_ankle_pitch_link">
    <inertial>
      <origin xyz="-0.007269 0 0.011137" rpy="0 0 0"/>
      <mass value="0.074"/>
      <inertia ixx="8.4E-06" ixy="0" ixz="-2.9E-06" iyy="1.89E-05" iyz="0" izz="1.26E-05"/>
    </inertial>
    <visual>
      <origin xyz="0 0 0" rpy="0 0 0"/>
      <geometry>
        <mesh filename="meshes/right_ankle_pitch_link.STL"/>
      </geometry>
      <material name="white">
        <color rgba="0.7 0.7 0.7 1"/>
      </material>
    </visual>
  </link>
  <joint name="right_ankle_pitch_joint" type="revolute">
    <origin xyz="0 9.4445E-05 -0.30001" rpy="0 0 0"/>
    <parent link="right_knee_link"/>
    <child link="right_ankle_pitch_link"/>
    <axis xyz="0 1 0"/>
    <limit lower="-0.87267" upper="0.5236" effort="50" velocity="12"/>
  </joint>
  <link name="right_ankle_roll_link">
    <visual>
      <origin xyz="0 0 0" rpy="0 0 0"/>
      <geometry>
        <mesh filename="meshes/right_ankle_roll_link.STL"/>
      </geometry>
      <material name="dark">
        <color rgba="0.2 0.2 0.2 1"/>
      </material>
    </visual>
    <collision>
      <origin xyz="-0.05 0.025 -0.03" rpy="0 0 0"/>
      <geometry>
        <sphere radius="0.005"/>
      </geometry>
    </collision>
    <collision>
      <origin xyz="-0.05 -0.025 -0.03" rpy="0 0 0"/>
      <geometry>
        <sphere radius="0.005"/>
      </geometry>
    </collision>
    <collision>
      <origin xyz="0.12 0.03 -0.03" rpy="0 0 0"/>
      <geometry>
        <sphere radius="0.005"/>
      </geometry>
    </collision>
    <collision>
      <origin xyz="0.12 -0.03 -0.03" rpy="0 0 0"/>
      <geometry>
        <sphere radius="0.005"/>
      </geometry>
    </collision>
    <inertial>
      <origin xyz="0.026505 0 -0.016425" rpy="0 0 0"/>
      <mass value="0.608"/>
      <inertia ixx="0.0002231" ixy="-2e-07" ixz="8.91e-05" iyy="0.0016161" iyz="1e-07" izz="0.0016667"/>
    </inertial>
  </link>
  <joint name="right_ankle_roll_joint" type="revolute">
    <origin xyz="0 0 -0.017558" rpy="0 0 0"/>
    <parent link="right_ankle_pitch_link"/>
    <child link="right_ankle_roll_link"/>
    <axis xyz="1 0 0"/>
    <limit lower="-0.2618" upper="0.2618" effort="50" velocity="12"/>
  </joint>
  <link name="waist_yaw_link">
    <visual>
      <origin xyz="0 0 0" rpy="0 0 0"/>
      <geometry>
        <mesh filename="meshes/waist_yaw_link.STL"/>
      </geometry>
      <material name="white">
        <color rgba="0.7 0.7 0.7 1"/>
      </material>
    </visual>
    <collision>
      <origin xyz="0.0 0.0 0.3" rpy="0 0 0"/>
      <geometry>
        <box size="0.12 0.175 0.4"/>
      </geometry>
    </collision>
    <visual>
      <origin xyz="-0.0039635 0 0.035" rpy="0 -0 0"/>
      <geometry>
        <mesh filename="meshes/waist_roll_link.STL"/>
      </geometry>
      <material name="white">
        <color rgba="0.7 0.7 0.7 1"/>
      </material>
    </visual>
    <visual>
      <origin xyz="-0.0039635 0 0.054" rpy="0 -0 0"/>
      <geometry>
        <mesh filename="meshes/torso_link.STL"/>
      </geometry>
      <material name="white">
        <color rgba="0.7 0.7 0.7 1"/>
      </material>
    </visual>
    <visual>
      <origin xyz="0 0 0" rpy="0 -0 0"/>
      <geometry>
        <mesh filename="meshes/logo_link.STL"/>
      </geometry>
      <material name="dark">
        <color rgba="0.2 0.2 0.2 1"/>
      </material>
    </visual>
    <visual>
      <origin xyz="0 0 0" rpy="0 -0 0"/>
      <geometry>
        <mesh filename="meshes/head_link.STL"/>
      </geometry>
      <material name="dark">
        <color rgba="0.2 0.2 0.2 1"/>
      </material>
    </visual>
    <inertial>
      <origin xyz="-0.0005488000712 0.0002526646446 0.2276063305" rpy="0 0 0"/>
      <mass value="9.891"/>
      <inertia ixx="0.1367432916" ixy="-9.039490836e-05" ixz="-0.003096130522" iyy="0.1247732792" iyz="5.604154645e-05" izz="0.03282234124"/>
    </inertial>
    <visual>
      <origin xyz="0 0 0" rpy="0 -0 0"/>
      <geometry>
        <mesh filename="meshes/waist_support_link.STL"/>
      </geometry>
      <material name="white">
        <color rgba="0.7 0.7 0.7 1"/>
      </material>
    </visual>
  </link>
  <joint name="waist_yaw_joint" type="revolute">
    <origin xyz="0 0 0" rpy="0 0 0"/>
    <parent link="pelvis_link"/>
    <child link="waist_yaw_link"/>
    <axis xyz="0 0 1"/>
    <limit lower="-2.618" upper="2.618" effort="88" velocity="12"/>
  </joint>
  <link name="left_shoulder_pitch_link">
    <inertial>
      <origin xyz="0 0.035892 -0.011628" rpy="0 0 0"/>
      <mass value="0.718"/>
      <inertia ixx="0.0004291" ixy="-9.2E-06" ixz="6.4E-06" iyy="0.000453" iyz="2.26E-05" izz="0.000423"/>
    </inertial>
    <visual>
      <origin xyz="0 0 0" rpy="0 0 0"/>
      <geometry>
        <mesh filename="meshes/left_shoulder_pitch_link.STL"/>
      </geometry>
      <material name="white">
        <color rgba="0.7 0.7 0.7 1"/>
      </material>
    </visual>
  </link>
  <joint name="left_shoulder_pitch_joint" type="revolute">
    <origin xyz="-7.2e-06 0.10022 0.29178" rpy="0.27931 5.4949e-05 -0.00019159"/>
    <parent link="waist_yaw_link"/>
    <child link="left_shoulder_pitch_link"/>
    <axis xyz="0 1 0"/>
    <limit lower="-3.0892" upper="2.6704" effort="25" velocity="12"/>
  </joint>
  <link name="left_shoulder_roll_link">
    <inertial>
      <origin xyz="-0.000227 0.00727 -0.063243" rpy="0 0 0"/>
      <mass value="0.643"/>
      <inertia ixx="0.0006177" ixy="-1E-06" ixz="8.7E-06" iyy="0.0006912" iyz="-5.3E-06" izz="0.0003894"/>
    </inertial>
    <visual>
      <origin xyz="0 0 0" rpy="0 0 0"/>
      <geometry>
        <mesh filename="meshes/left_shoulder_roll_link.STL"/>
      </geometry>
      <material name="white">
        <color rgba="0.7 0.7 0.7 1"/>
      </material>
    </visual>
  </link>
  <joint name="left_shoulder_roll_joint" type="revolute">
    <origin xyz="0 0.038 -0.013831" rpy="-0.27925 0 0"/>
    <parent link="left_shoulder_pitch_link"/>
    <child link="left_shoulder_roll_link"/>
    <axis xyz="1 0 0"/>
    <limit lower="-1.5882" upper="2.2515" effort="25" velocity="12"/>
  </joint>
  <link name="left_shoulder_yaw_link">
    <inertial>
      <origin xyz="0.010773 -0.002949 -0.072009" rpy="0 0 0"/>
      <mass value="0.734"/>
      <inertia ixx="0.0009988" ixy="7.9E-06" ixz="0.0001412" iyy="0.0010605" iyz="-2.86E-05" izz="0.0004354"/>
    </inertial>
    <visual>
      <origin xyz="0 0 0" rpy="0 0 0"/>
      <geometry>
        <mesh filename="meshes/left_shoulder_yaw_link.STL"/>
      </geometry>
      <material name="white">
        <color rgba="0.7 0.7 0.7 1"/>
      </material>
    </visual>
  </link>
  <joint name="left_shoulder_yaw_joint" type="revolute">
    <origin xyz="0 0.00624 -0.1032" rpy="0 0 0"/>
    <parent link="left_shoulder_roll_link"/>
    <child link="left_shoulder_yaw_link"/>
    <axis xyz="0 0 1"/>
    <limit lower="-2.618" upper="2.618" effort="25" velocity="12"/>
  </joint>
  <link name="left_elbow_link">
    <inertial>
      <origin xyz="0.064956 0.004454 -0.010062" rpy="0 0 0"/>
      <mass value="0.6"/>
      <inertia ixx="0.0002891" ixy="6.53E-05" ixz="1.72E-05" iyy="0.0004152" iyz="-5.6E-06" izz="0.0004197"/>
    </inertial>
    <visual>
      <origin xyz="0 0 0" rpy="0 0 0"/>
      <geometry>
        <mesh filename="meshes/left_elbow_link.STL"/>
      </geometry>
      <material name="white">
        <color rgba="0.7 0.7 0.7 1"/>
      </material>
    </visual>
    <collision>
      <origin xyz="0.11 0 -0.01" rpy="0 1.57 0"/>
      <geometry>
        <cylinder radius="0.035" length="0.22"/>
      </geometry>
    </collision>
  </link>
  <joint name="left_elbow_joint" type="revolute">
    <origin xyz="0.015783 0 -0.080518" rpy="0 0 0"/>
    <parent link="left_shoulder_yaw_link"/>
    <child link="left_elbow_link"/>
    <axis xyz="0 1 0"/>
    <limit lower="-1.0472" upper="2.0944" effort="25" velocity="12"/>
  </joint>
  <joint name="left_wrist_roll_joint" type="fixed">
    <origin xyz="0.100 0.00188791 -0.010" rpy="0 0 0"/>
    <axis xyz="1 0 0"/>
    <parent link="left_elbow_link"/>
    <child link="left_wrist_roll_link"/>
    <limit effort="25" velocity="12" lower="-1.972222054" upper="1.972222054"/>
  </joint>
  <link name="left_wrist_roll_link">
    <inertial>
      <origin xyz="0.01713944778 0.00053759094 0.00000048864" rpy="0 0 0"/>
      <mass value="0.08544498"/>
      <inertia ixx="0.00004821544023" ixy="-0.00000424511021" ixz="0.00000000510599" iyy="0.00003722899093" iyz="-0.00000000123525" izz="0.00005482106541"/>
    </inertial>
    <visual>
      <origin xyz="0 0 0" rpy="0 0 0"/>
      <geometry>
        <mesh filename="meshes/left_wrist_roll_link.STL"/>
      </geometry>
      <material name="white">
        <color rgba="0.7 0.7 0.7 1"/>
      </material>
    </visual>
  </link>
  <joint name="left_wrist_pitch_joint" type="fixed">
    <origin xyz="0.038 0 0" rpy="0 0 0"/>
    <axis xyz="0 1 0"/>
    <parent link="left_wrist_roll_link"/>
    <child link="left_wrist_pitch_link"/>
    <limit effort="5" velocity="22" lower="-1.614429558" upper="1.614429558"/>
  </joint>
  <link name="left_wrist_pitch_link">
    <inertial>
      <origin xyz="0.02299989837 -0.00111685314 -0.00111658096" rpy="0 0 0"/>
      <mass value="0.48404956"/>
      <inertia ixx="0.00016579646273" ixy="-0.00001231206746" ixz="0.00001231699194" iyy="0.00042954057410" iyz="0.00000081417712" izz="0.00042953697654"/>
    </inertial>
    <visual>
      <origin xyz="0 0 0" rpy="0 0 0"/>
      <geometry>
        <mesh filename="meshes/left_wrist_pitch_link.STL"/>
      </geometry>
      <material name="white">
        <color rgba="0.7 0.7 0.7 1"/>
      </material>
    </visual>
  </link>
  <joint name="left_wrist_yaw_joint" type="fixed">
    <origin xyz="0.046 0 0" rpy="0 0 0"/>
    <axis xyz="0 0 1"/>
    <parent link="left_wrist_pitch_link"/>
    <child link="left_wrist_yaw_link"/>
    <limit effort="5" velocity="22" lower="-1.614429558" upper="1.614429558"/>
  </joint>
  <link name="left_wrist_yaw_link">
    <visual>
      <origin xyz="0 0 0" rpy="0 0 0"/>
      <geometry>
        <mesh filename="meshes/left_wrist_yaw_link.STL"/>
      </geometry>
      <material name="white">
        <color rgba="0.7 0.7 0.7 1"/>
      </material>
    </visual>
    <collision>
      <origin xyz="0.1 -0.018 0.0" rpy="0 0 0"/>
      <geometry>
        <sphere radius="0.055"/>
      </geometry>
    </collision>
    <visual>
      <origin xyz="0.0415 0.003 0" rpy="0 -0 0"/>
      <geometry>
        <mesh filename="meshes/left_hand_palm_link.STL"/>
      </geometry>
      <material name="white">
        <color rgba="0.7 0.7 0.7 1"/>
      </material>
    </visual>
    <visual>
      <origin xyz="0.067 0.003 0" rpy="0 -0 0"/>
      <geometry>
        <mesh filename="meshes/left_hand_thumb_0_link.STL"/>
      </geometry>
      <material name="white">
        <color rgba="0.7 0.7 0.7 1"/>
      </material>
    </visual>
    <visual>
      <origin xyz="0.0645 -0.0163 0" rpy="0 -0 0"/>
      <geometry>
        <mesh filename="meshes/left_hand_thumb_1_link.STL"/>
      </geometry>
      <material name="white">
        <color rgba="0.7 0.7 0.7 1"/>
      </material>
    </visual>
    <visual>
      <origin xyz="0.0645 -0.0621 0" rpy="0 -0 1.57"/>
      <geometry>
        <mesh filename="meshes/left_hand_thumb_2_link.STL"/>
      </geometry>
      <material name="white">
        <color rgba="0.7 0.7 0.7 1"/>
      </material>
    </visual>
    <visual>
      <origin xyz="0.1192 0.0046 -0.0285" rpy="0 -0 -1.57"/>
      <geometry>
        <mesh filename="meshes/left_hand_middle_0_link.STL"/>
      </geometry>
      <material name="white">
        <color rgba="0.7 0.7 0.7 1"/>
      </material>
    </visual>
    <visual>
      <origin xyz="0.1192364718 -0.04119998548 -0.0285" rpy="0 -0 -3.14"/>
      <geometry>
        <mesh filename="meshes/left_hand_middle_1_link.STL"/>
      </geometry>
      <material name="white">
        <color rgba="0.7 0.7 0.7 1"/>
      </material>
    </visual>
    <visual>
      <origin xyz="0.1192 0.0046 0.0285" rpy="0 -0 -1.57"/>
      <geometry>
        <mesh filename="meshes/left_hand_index_0_link.STL"/>
      </geometry>
      <material name="white">
        <color rgba="0.7 0.7 0.7 1"/>
      </material>
    </visual>
    <inertial>
      <origin xyz="0.08923379573 -0.0118252745 -8.919264166e-05" rpy="0 0 0"/>
      <mass value="0.78112246"/>
      <inertia ixx="0.000835849357" ixy="4.986191308e-06" ixz="8.892111821e-06" iyy="0.001431187274" iyz="1.761055072e-06" izz="0.001480713877"/>
    </inertial>
    <visual>
      <origin xyz="0.1192364718 -0.04119998548 0.0285" rpy="0 -0 -3.14"/>
      <geometry>
        <mesh filename="meshes/left_hand_index_1_link.STL"/>
      </geometry>
      <material name="white">
        <color rgba="0.7 0.7 0.7 1"/>
      </material>
    </visual>
  </link>
  <link name="right_shoulder_pitch_link">
    <inertial>
      <origin xyz="0 -0.035892 -0.011628" rpy="0 0 0"/>
      <mass value="0.718"/>
      <inertia ixx="0.0004291" ixy="9.2E-06" ixz="6.4E-06" iyy="0.000453" iyz="-2.26E-05" izz="0.000423"/>
    </inertial>
    <visual>
      <origin xyz="0 0 0" rpy="0 0 0"/>
      <geometry>
        <mesh filename="meshes/right_shoulder_pitch_link.STL"/>
      </geometry>
      <material name="white">
        <color rgba="0.7 0.7 0.7 1"/>
      </material>
    </visual>
  </link>
  <joint name="right_shoulder_pitch_joint" type="revolute">
    <origin xyz="-7.2e-06 -0.10021 0.29178" rpy="-0.27931 5.4949e-05 0.00019159"/>
    <parent link="waist_yaw_link"/>
    <child link="right_shoulder_pitch_link"/>
    <axis xyz="0 1 0"/>
    <limit lower="-3.0892" upper="2.6704" effort="25" velocity="12"/>
  </joint>
  <link name="right_shoulder_roll_link">
    <inertial>
      <origin xyz="-0.000227 -0.00727 -0.063243" rpy="0 0 0"/>
      <mass value="0.643"/>
      <inertia ixx="0.0006177" ixy="1E-06" ixz="8.7E-06" iyy="0.0006912" iyz="5.3E-06" izz="0.0003894"/>
    </inertial>
    <visual>
      <origin xyz="0 0 0" rpy="0 0 0"/>
      <geometry>
        <mesh filename="meshes/right_shoulder_roll_link.STL"/>
      </geometry>
      <material name="white">
        <color rgba="0.7 0.7 0.7 1"/>
      </material>
    </visual>
  </link>
  <joint name="right_shoulder_roll_joint" type="revolute">
    <origin xyz="0 -0.038 -0.013831" rpy="0.27925 0 0"/>
    <parent link="right_shoulder_pitch_link"/>
    <child link="right_shoulder_roll_link"/>
    <axis xyz="1 0 0"/>
    <limit lower="-2.2515" upper="1.5882" effort="25" velocity="12"/>
  </joint>
  <link name="right_shoulder_yaw_link">
    <inertial>
      <origin xyz="0.010773 0.002949 -0.072009" rpy="0 0 0"/>
      <mass value="0.734"/>
      <inertia ixx="0.0009988" ixy="-7.9E-06" ixz="0.0001412" iyy="0.0010605" iyz="2.86E-05" izz="0.0004354"/>
    </inertial>
    <visual>
      <origin xyz="0 0 0" rpy="0 0 0"/>
      <geometry>
        <mesh filename="meshes/right_shoulder_yaw_link.STL"/>
      </geometry>
      <material name="white">
        <color rgba="0.7 0.7 0.7 1"/>
      </material>
    </visual>
  </link>
  <joint name="right_shoulder_yaw_joint" type="revolute">
    <origin xyz="0 -0.00624 -0.1032" rpy="0 0 0"/>
    <parent link="right_shoulder_roll_link"/>
    <child link="right_shoulder_yaw_link"/>
    <axis xyz="0 0 1"/>
    <limit lower="-2.618" upper="2.618" effort="25" velocity="12"/>
  </joint>
  <link name="right_elbow_link">
    <inertial>
      <origin xyz="0.064956 -0.004454 -0.010062" rpy="0 0 0"/>
      <mass value="0.6"/>
      <inertia ixx="0.0002891" ixy="-6.53E-05" ixz="1.72E-05" iyy="0.0004152" iyz="5.6E-06" izz="0.0004197"/>
    </inertial>
    <visual>
      <origin xyz="0 0 0" rpy="0 0 0"/>
      <geometry>
        <mesh filename="meshes/right_elbow_link.STL"/>
      </geometry>
      <material name="white">
        <color rgba="0.7 0.7 0.7 1"/>
      </material>
    </visual>
    <collision>
      <origin xyz="0.11 0 -0.01" rpy="0 1.57 0"/>
      <geometry>
        <cylinder radius="0.035" length="0.22"/>
      </geometry>
    </collision>
  </link>
  <joint name="right_elbow_joint" type="revolute">
    <origin xyz="0.015783 0 -0.080518" rpy="0 0 0"/>
    <parent link="right_shoulder_yaw_link"/>
    <child link="right_elbow_link"/>
    <axis xyz="0 1 0"/>
    <limit lower="-1.0472" upper="2.0944" effort="25" velocity="12"/>
  </joint>
  <joint name="right_wrist_roll_joint" type="fixed">
    <origin xyz="0.100 -0.00188791 -0.010" rpy="0 0 0"/>
    <axis xyz="1 0 0"/>
    <parent link="right_elbow_link"/>
    <child link="right_wrist_roll_link"/>
    <limit effort="25" velocity="12" lower="-1.972222054" upper="1.972222054"/>
  </joint>
  <link name="right_wrist_roll_link">
    <inertial>
      <origin xyz="0.01713944778 -0.00053759094 0.00000048864" rpy="0 0 0"/>
      <mass value="0.08544498"/>
      <inertia ixx="0.00004821544023" ixy="0.00000424511021" ixz="0.00000000510599" iyy="0.00003722899093" iyz="0.00000000123525" izz="0.00005482106541"/>
    </inertial>
    <visual>
      <origin xyz="0 0 0" rpy="0 0 0"/>
      <geometry>
        <mesh filename="meshes/right_wrist_roll_link.STL"/>
      </geometry>
      <material name="white">
        <color rgba="0.7 0.7 0.7 1"/>
      </material>
    </visual>
  </link>
  <joint name="right_wrist_pitch_joint" type="fixed">
    <origin xyz="0.038 0 0" rpy="0 0 0"/>
    <axis xyz="0 1 0"/>
    <parent link="right_wrist_roll_link"/>
    <child link="right_wrist_pitch_link"/>
    <limit effort="5" velocity="22" lower="-1.614429558" upper="1.614429558"/>
  </joint>
  <link name="right_wrist_pitch_link">
    <inertial>
      <origin xyz="0.02299989837 0.00111685314 -0.00111658096" rpy="0 0 0"/>
      <mass value="0.48404956"/>
      <inertia ixx="0.00016579646273" ixy="0.00001231206746" ixz="0.00001231699194" iyy="0.00042954057410" iyz="-0.00000081417712" izz="0.00042953697654"/>
    </inertial>
    <visual>
      <origin xyz="0 0 0" rpy="0 0 0"/>
      <geometry>
        <mesh filename="meshes/right_wrist_pitch_link.STL"/>
      </geometry>
      <material name="white">
        <color rgba="0.7 0.7 0.7 1"/>
      </material>
    </visual>
  </link>
  <joint name="right_wrist_yaw_joint" type="fixed">
    <origin xyz="0.046 0 0" rpy="0 0 0"/>
    <axis xyz="0 0 1"/>
    <parent link="right_wrist_pitch_link"/>
    <child link="right_wrist_yaw_link"/>
    <limit effort="5" velocity="22" lower="-1.614429558" upper="1.614429558"/>
  </joint>
  <link name="right_wrist_yaw_link">
    <visual>
      <origin xyz="0 0 0" rpy="0 0 0"/>
      <geometry>
        <mesh filename="meshes/right_wrist_yaw_link.STL"/>
      </geometry>
      <material name="white">
        <color rgba="0.7 0.7 0.7 1"/>
      </material>
    </visual>
    <collision>
      <origin xyz="0.1 0.018 0.0" rpy="0 0 0"/>
      <geometry>
        <sphere radius="0.055"/>
      </geometry>
    </collision>
    <visual>
      <origin xyz="0.0415 -0.003 0" rpy="0 -0 0"/>
      <geometry>
        <mesh filename="meshes/right_hand_palm_link.STL"/>
      </geometry>
      <material name="white">
        <color rgba="0.7 0.7 0.7 1"/>
      </material>
    </visual>
    <visual>
      <origin xyz="0.067 -0.003 0" rpy="0 -0 0"/>
      <geometry>
        <mesh filename="meshes/right_hand_thumb_0_link.STL"/>
      </geometry>
      <material name="white">
        <color rgba="0.7 0.7 0.7 1"/>
      </material>
    </visual>
    <visual>
      <origin xyz="0.0645 0.0163 0" rpy="0 -0 0"/>
      <geometry>
        <mesh filename="meshes/right_hand_thumb_1_link.STL"/>
      </geometry>
      <material name="white">
        <color rgba="0.7 0.7 0.7 1"/>
      </material>
    </visual>
    <visual>
      <origin xyz="0.0645 0.0621 0" rpy="0 -0 -1.57"/>
      <geometry>
        <mesh filename="meshes/right_hand_thumb_2_link.STL"/>
      </geometry>
      <material name="white">
        <color rgba="0.7 0.7 0.7 1"/>
      </material>
    </visual>
    <visual>
      <origin xyz="0.1192 -0.0046 -0.0285" rpy="0 -0 1.57"/>
      <geometry>
        <mesh filename="meshes/right_hand_middle_0_link.STL"/>
      </geometry>
      <material name="white">
        <color rgba="0.7 0.7 0.7 1"/>
      </material>
    </visual>
    <visual>
      <origin xyz="0.1192364718 0.04119998548 -0.0285" rpy="0 -0 3.14"/>
      <geometry>
        <mesh filename="meshes/right_hand_middle_1_link.STL"/>
      </geometry>
      <material name="white">
        <color rgba="0.7 0.7 0.7 1"/>
      </material>
    </visual>
    <visual>
      <origin xyz="0.1192 -0.0046 0.0285" rpy="0 -0 1.57"/>
      <geometry>
        <mesh filename="meshes/right_hand_index_0_link.STL"/>
      </geometry>
      <material name="white">
        <color rgba="0.7 0.7 0.7 1"/>
      </material>
    </visual>
    <inertial>
      <origin xyz="0.08923379573 0.0118252745 -8.919264166e-05" rpy="0 0 0"/>
      <mass value="0.78112246"/>
      <inertia ixx="0.000835849357" ixy="-4.986191308e-06" ixz="8.892111821e-06" iyy="0.001431187274" iyz="-1.761055072e-06" izz="0.001480713877"/>
    </inertial>
    <visual>
      <origin xyz="0.1192364718 0.04119998548 0.0285" rpy="0 -0 3.14"/>
      <geometry>
        <mesh filename="meshes/right_hand_index_1_link.STL"/>
      </geometry>
      <material name="white">
        <color rgba="0.7 0.7 0.7 1"/>
      </material>
    </visual>
  </link>
</robot>
